Workbook

Sheet OWNED
A1: name | B1: bgg_id | C1: label | D1: check_unique | E1: bgg_name | F1: check_name | G1: category | H1: lib_cat_chk | I1: nz_desgn | O1: {=IFERROR(_xlfn._xlws.FILTER(OWNED[bgg_id], ISNA(MATCH(OWNED[bgg_id], library_data[bgg_id], 0))),"OWNED AND LIBRARY MATCH")} -> 247367
A2: 7 Wonders | B2: 68448 | D2: =COUNTIF(OWNED[bgg_id],OWNED[[#This Row],[bgg_id]]) -> 1 | E2: =_xlfn.XLOOKUP(OWNED[[#This Row],[bgg_id]],bgg_cache[id],bgg_cache[title]) -> 7 Wonders | F2: =EXACT(OWNED[[#This Row],[name]],OWNED[[#This Row],[bgg_name]]) -> TRUE | G2: GATEWAY_STRATEGY | H2: =_xlfn.XLOOKUP(OWNED[[#This Row],[bgg_id]],library_data[bgg_id],library_data[mana_meeple_category])=OWNED[[#This Row],[category]] -> TRUE | I2: =COUNTIF(nzdesgn[NAME],OWNED[[#This Row],[bgg_name]]) -> 0 | O2: 155426
A3: 7 Wonders Duel | B3: 173346 | D3: =COUNTIF(OWNED[bgg_id],OWNED[[#This Row],[bgg_id]]) -> 1 | E3: =_xlfn.XLOOKUP(OWNED[[#This Row],[bgg_id]],bgg_cache[id],bgg_cache[title]) -> 7 Wonders Duel | F3: =EXACT(OWNED[[#This Row],[name]],OWNED[[#This Row],[bgg_name]]) -> TRUE | G3: GATEWAY_STRATEGY | H3: =_xlfn.XLOOKUP(OWNED[[#This Row],[bgg_id]],library_data[bgg_id],library_data[mana_meeple_category])=OWNED[[#This Row],[category]] -> TRUE | I3: =COUNTIF(nzdesgn[NAME],OWNED[[#This Row],[bgg_name]]) -> 0 | O3: 348096
A4: A Feast for Odin | B4: 177736 | D4: =COUNTIF(OWNED[bgg_id],OWNED[[#This Row],[bgg_id]]) -> 1 | E4: =_xlfn.XLOOKUP(OWNED[[#This Row],[bgg_id]],bgg_cache[id],bgg_cache[title]) -> A Feast for Odin | F4: =EXACT(OWNED[[#This Row],[name]],OWNED[[#This Row],[bgg_name]]) -> TRUE | G4: CORE_STRATEGY | H4: =_xlfn.XLOOKUP(OWNED[[#This Row],[bgg_id]],library_data[bgg_id],library_data[mana_meeple_category])=OWNED[[#This Row],[category]] -> TRUE | I4: =COUNTIF(nzdesgn[NAME],OWNED[[#This Row],[bgg_name]]) -> 0 | O4: 312484
A5: Abandon All Artichokes | B5: 302260 | D5: =COUNTIF(OWNED[bgg_id],OWNED[[#This Row],[bgg_id]]) -> 1 | E5: =_xlfn.XLOOKUP(OWNED[[#This Row],[bgg_id]],bgg_cache[id],bgg_cache[title]) -> Abandon All Artichokes | F5: =EXACT(OWNED[[#This Row],[name]],OWNED[[#This Row],[bgg_name]]) -> TRUE | G5: KIDS_FAMILIES | H5: =_xlfn.XLOOKUP(OWNED[[#This Row],[bgg_id]],library_data[bgg_id],library_data[mana_meeple_category])=OWNED[[#This Row],[category]] -> TRUE | I5: =COUNTIF(nzdesgn[NAME],OWNED[[#This Row],[bgg_name]]) -> 0 | O5: 156546
A6: =_xlfn.XLOOKUP(OWNED[[#This Row],[bgg_id]],bgg_cache[id],bgg_cache[title]) -> Air, Land, & Sea | B6: 247367 | C6: 1 | D6: =COUNTIF(OWNED[bgg_id],OWNED[[#This Row],[bgg_id]]) -> 1 | E6: =_xlfn.XLOOKUP(OWNED[[#This Row],[bgg_id]],bgg_cache[id],bgg_cache[title]) -> Air, Land, & Sea | F6: =EXACT(OWNED[[#This Row],[name]],OWNED[[#This Row],[bgg_name]]) -> TRUE | H6: =_xlfn.XLOOKUP(OWNED[[#This Row],[bgg_id]],library_data[bgg_id],library_data[mana_meeple_category])=OWNED[[#This Row],[category]] -> #N/A | I6: =COUNTIF(nzdesgn[NAME],OWNED[[#This Row],[bgg_name]]) -> 0 | L6: Row Labels | M6: Count of NAME | O6: 353545
A7: Akropolis | B7: 357563 | D7: =COUNTIF(OWNED[bgg_id],OWNED[[#This Row],[bgg_id]]) -> 1 | E7: =_xlfn.XLOOKUP(OWNED[[#This Row],[bgg_id]],bgg_cache[id],bgg_cache[title]) -> Akropolis | F7: =EXACT(OWNED[[#This Row],[name]],OWNED[[#This Row],[bgg_name]]) -> TRUE | G7: GATEWAY_STRATEGY | H7: =_xlfn.XLOOKUP(OWNED[[#This Row],[bgg_id]],library_data[bgg_id],library_data[mana_meeple_category])=OWNED[[#This Row],[category]] -> TRUE | I7: =COUNTIF(nzdesgn[NAME],OWNED[[#This Row],[bgg_name]]) -> 0 | L7: COOP_ADVENTURE | M7: 36 | O7: 367272
A8: Animal Upon Animal | B8: 17329 | D8: =COUNTIF(OWNED[bgg_id],OWNED[[#This Row],[bgg_id]]) -> 1 | E8: =_xlfn.XLOOKUP(OWNED[[#This Row],[bgg_id]],bgg_cache[id],bgg_cache[title]) -> Animal Upon Animal | F8: =EXACT(OWNED[[#This Row],[name]],OWNED[[#This Row],[bgg_name]]) -> TRUE | G8: KIDS_FAMILIES | H8: =_xlfn.XLOOKUP(OWNED[[#This Row],[bgg_id]],library_data[bgg_id],library_data[mana_meeple_category])=OWNED[[#This Row],[category]] -> TRUE | I8: =COUNTIF(nzdesgn[NAME],OWNED[[#This Row],[bgg_name]]) -> 0 | L8: CORE_STRATEGY | M8: 25 | O8: 305682
A9: Anomia | B9: 67877 | D9: =COUNTIF(OWNED[bgg_id],OWNED[[#This Row],[bgg_id]]) -> 1 | E9: =_xlfn.XLOOKUP(OWNED[[#This Row],[bgg_id]],bgg_cache[id],bgg_cache[title]) -> Anomia | F9: =EXACT(OWNED[[#This Row],[name]],OWNED[[#This Row],[bgg_name]]) -> TRUE | G9: PARTY_ICEBREAKERS | H9: =_xlfn.XLOOKUP(OWNED[[#This Row],[bgg_id]],library_data[bgg_id],library_data[mana_meeple_category])=OWNED[[#This Row],[category]] -> TRUE | I9: =COUNTIF(nzdesgn[NAME],OWNED[[#This Row],[bgg_name]]) -> 0 | L9: GATEWAY_STRATEGY | M9: 49 | O9: 284083
A10: Ascension: Deckbuilding Game | B10: 69789 | D10: =COUNTIF(OWNED[bgg_id],OWNED[[#This Row],[bgg_id]]) -> 1 | E10: =_xlfn.XLOOKUP(OWNED[[#This Row],[bgg_id]],bgg_cache[id],bgg_cache[title]) -> Ascension: Deckbuilding Game | F10: =EXACT(OWNED[[#This Row],[name]],OWNED[[#This Row],[bgg_name]]) -> TRUE | G10: GATEWAY_STRATEGY | H10: =_xlfn.XLOOKUP(OWNED[[#This Row],[bgg_id]],library_data[bgg_id],library_data[mana_meeple_category])=OWNED[[#This Row],[category]] -> TRUE | I10: =COUNTIF(nzdesgn[NAME],OWNED[[#This Row],[bgg_name]]) -> 0 | L10: KIDS_FAMILIES | M10: 25 | O10: 314421
A11: Azul | B11: 230802 | D11: =COUNTIF(OWNED[bgg_id],OWNED[[#This Row],[bgg_id]]) -> 1 | E11: =_xlfn.XLOOKUP(OWNED[[#This Row],[bgg_id]],bgg_cache[id],bgg_cache[title]) -> Azul | F11: =EXACT(OWNED[[#This Row],[name]],OWNED[[#This Row],[bgg_name]]) -> TRUE | G11: GATEWAY_STRATEGY | H11: =_xlfn.XLOOKUP(OWNED[[#This Row],[bgg_id]],library_data[bgg_id],library_data[mana_meeple_category])=OWNED[[#This Row],[category]] -> TRUE | I11: =COUNTIF(nzdesgn[NAME],OWNED[[#This Row],[bgg_name]]) -> 0 | L11: PARTY_ICEBREAKERS | M11: 51 | O11: 257527
A12: Battlestar Galactica: The Board Game | B12: 37111 | D12: =COUNTIF(OWNED[bgg_id],OWNED[[#This Row],[bgg_id]]) -> 1 | E12: =_xlfn.XLOOKUP(OWNED[[#This Row],[bgg_id]],bgg_cache[id],bgg_cache[title]) -> Battlestar Galactica: The Board Game | F12: =EXACT(OWNED[[#This Row],[name]],OWNED[[#This Row],[bgg_name]]) -> TRUE | G12: CORE_STRATEGY | H12: =_xlfn.XLOOKUP(OWNED[[#This Row],[bgg_id]],library_data[bgg_id],library_data[mana_meeple_category])=OWNED[[#This Row],[category]] -> TRUE | I12: =COUNTIF(nzdesgn[NAME],OWNED[[#This Row],[bgg_name]]) -> 0 | L12: (blank) | M12: 18 | O12: 233867
A13: Bohnanza | B13: 11 | D13: =COUNTIF(OWNED[bgg_id],OWNED[[#This Row],[bgg_id]]) -> 1 | E13: =_xlfn.XLOOKUP(OWNED[[#This Row],[bgg_id]],bgg_cache[id],bgg_cache[title]) -> Bohnanza | F13: =EXACT(OWNED[[#This Row],[name]],OWNED[[#This Row],[bgg_name]]) -> TRUE | G13: GATEWAY_STRATEGY | H13: =_xlfn.XLOOKUP(OWNED[[#This Row],[bgg_id]],library_data[bgg_id],library_data[mana_meeple_category])=OWNED[[#This Row],[category]] -> TRUE | I13: =COUNTIF(nzdesgn[NAME],OWNED[[#This Row],[bgg_name]]) -> 0 | L13: Grand Total | M13: 204 | O13: 9209
A14: BUILDZI | B14: 326243 | D14: =COUNTIF(OWNED[bgg_id],OWNED[[#This Row],[bgg_id]]) -> 1 | E14: =_xlfn.XLOOKUP(OWNED[[#This Row],[bgg_id]],bgg_cache[id],bgg_cache[title]) -> BUILDZI | F14: =EXACT(OWNED[[#This Row],[name]],OWNED[[#This Row],[bgg_name]]) -> TRUE | G14: KIDS_FAMILIES | H14: =_xlfn.XLOOKUP(OWNED[[#This Row],[bgg_id]],library_data[bgg_id],library_data[mana_meeple_category])=OWNED[[#This Row],[category]] -> TRUE | I14: =COUNTIF(nzdesgn[NAME],OWNED[[#This Row],[bgg_name]]) -> 0 | O14: 304783
A15: Calico | B15: 283155 | D15: =COUNTIF(OWNED[bgg_id],OWNED[[#This Row],[bgg_id]]) -> 1 | E15: =_xlfn.XLOOKUP(OWNED[[#This Row],[bgg_id]],bgg_cache[id],bgg_cache[title]) -> Calico | F15: =EXACT(OWNED[[#This Row],[name]],OWNED[[#This Row],[bgg_name]]) -> TRUE | G15: GATEWAY_STRATEGY | H15: =_xlfn.XLOOKUP(OWNED[[#This Row],[bgg_id]],library_data[bgg_id],library_data[mana_meeple_category])=OWNED[[#This Row],[category]] -> TRUE | I15: =COUNTIF(nzdesgn[NAME],OWNED[[#This Row],[bgg_name]]) -> 0 | O15: 329839
A16: Camel Up (Second Edition) | B16: 260605 | D16: =COUNTIF(OWNED[bgg_id],OWNED[[#This Row],[bgg_id]]) -> 1 | E16: =_xlfn.XLOOKUP(OWNED[[#This Row],[bgg_id]],bgg_cache[id],bgg_cache[title]) -> Camel Up (Second Edition) | F16: =EXACT(OWNED[[#This Row],[name]],OWNED[[#This Row],[bgg_name]]) -> TRUE | G16: PARTY_ICEBREAKERS | H16: =_xlfn.XLOOKUP(OWNED[[#This Row],[bgg_id]],library_data[bgg_id],library_data[mana_meeple_category])=OWNED[[#This Row],[category]] -> TRUE | I16: =COUNTIF(nzdesgn[NAME],OWNED[[#This Row],[bgg_name]]) -> 0 | O16: 223278
A17: Captain Sonar | B17: 171131 | D17: =COUNTIF(OWNED[bgg_id],OWNED[[#This Row],[bgg_id]]) -> 1 | E17: =_xlfn.XLOOKUP(OWNED[[#This Row],[bgg_id]],bgg_cache[id],bgg_cache[title]) -> Captain Sonar | F17: =EXACT(OWNED[[#This Row],[name]],OWNED[[#This Row],[bgg_name]]) -> TRUE | G17: COOP_ADVENTURE | H17: =_xlfn.XLOOKUP(OWNED[[#This Row],[bgg_id]],library_data[bgg_id],library_data[mana_meeple_category])=OWNED[[#This Row],[category]] -> TRUE | I17: =COUNTIF(nzdesgn[NAME],OWNED[[#This Row],[bgg_name]]) -> 0 | O17: 48726
A18: Carcassonne | B18: 822 | D18: =COUNTIF(OWNED[bgg_id],OWNED[[#This Row],[bgg_id]]) -> 1 | E18: =_xlfn.XLOOKUP(OWNED[[#This Row],[bgg_id]],bgg_cache[id],bgg_cache[title]) -> Carcassonne | F18: =EXACT(OWNED[[#This Row],[name]],OWNED[[#This Row],[bgg_name]]) -> TRUE | G18: GATEWAY_STRATEGY | H18: =_xlfn.XLOOKUP(OWNED[[#This Row],[bgg_id]],library_data[bgg_id],library_data[mana_meeple_category])=OWNED[[#This Row],[category]] -> TRUE | I18: =COUNTIF(nzdesgn[NAME],OWNED[[#This Row],[bgg_name]]) -> 0
A19: Cartographers | B19: 263918 | D19: =COUNTIF(OWNED[bgg_id],OWNED[[#This Row],[bgg_id]]) -> 1 | E19: =_xlfn.XLOOKUP(OWNED[[#This Row],[bgg_id]],bgg_cache[id],bgg_cache[title]) -> Cartographers | F19: =EXACT(OWNED[[#This Row],[name]],OWNED[[#This Row],[bgg_name]]) -> TRUE | G19: GATEWAY_STRATEGY | H19: =_xlfn.XLOOKUP(OWNED[[#This Row],[bgg_id]],library_data[bgg_id],library_data[mana_meeple_category])=OWNED[[#This Row],[category]] -> TRUE | I19: =COUNTIF(nzdesgn[NAME],OWNED[[#This Row],[bgg_name]]) -> 0
A20: Cascadia | B20: 295947 | D20: =COUNTIF(OWNED[bgg_id],OWNED[[#This Row],[bgg_id]]) -> 1 | E20: =_xlfn.XLOOKUP(OWNED[[#This Row],[bgg_id]],bgg_cache[id],bgg_cache[title]) -> Cascadia | F20: =EXACT(OWNED[[#This Row],[name]],OWNED[[#This Row],[bgg_name]]) -> TRUE | G20: GATEWAY_STRATEGY | H20: =_xlfn.XLOOKUP(OWNED[[#This Row],[bgg_id]],library_data[bgg_id],library_data[mana_meeple_category])=OWNED[[#This Row],[category]] -> TRUE | I20: =COUNTIF(nzdesgn[NAME],OWNED[[#This Row],[bgg_name]]) -> 0
A21: Castles of Mad King Ludwig | B21: 155426 | C21: 1 | D21: =COUNTIF(OWNED[bgg_id],OWNED[[#This Row],[bgg_id]]) -> 1 | E21: =_xlfn.XLOOKUP(OWNED[[#This Row],[bgg_id]],bgg_cache[id],bgg_cache[title]) -> #N/A | F21: =EXACT(OWNED[[#This Row],[name]],OWNED[[#This Row],[bgg_name]]) -> #N/A | H21: =_xlfn.XLOOKUP(OWNED[[#This Row],[bgg_id]],library_data[bgg_id],library_data[mana_meeple_category])=OWNED[[#This Row],[category]] -> #N/A | I21: =COUNTIF(nzdesgn[NAME],OWNED[[#This Row],[bgg_name]]) -> 0
A22: CATAN | B22: 13 | D22: =COUNTIF(OWNED[bgg_id],OWNED[[#This Row],[bgg_id]]) -> 1 | E22: =_xlfn.XLOOKUP(OWNED[[#This Row],[bgg_id]],bgg_cache[id],bgg_cache[title]) -> CATAN | F22: =EXACT(OWNED[[#This Row],[name]],OWNED[[#This Row],[bgg_name]]) -> TRUE | G22: GATEWAY_STRATEGY | H22: =_xlfn.XLOOKUP(OWNED[[#This Row],[bgg_id]],library_data[bgg_id],library_data[mana_meeple_category])=OWNED[[#This Row],[category]] -> TRUE | I22: =COUNTIF(nzdesgn[NAME],OWNED[[#This Row],[bgg_name]]) -> 0
A23: Category 5 aka. 6 nimmt! aka. Take 5 | B23: 432 | D23: =COUNTIF(OWNED[bgg_id],OWNED[[#This Row],[bgg_id]]) -> 1 | E23: =_xlfn.XLOOKUP(OWNED[[#This Row],[bgg_id]],bgg_cache[id],bgg_cache[title]) -> Take 5 | F23: =EXACT(OWNED[[#This Row],[name]],OWNED[[#This Row],[bgg_name]]) -> FALSE | G23: PARTY_ICEBREAKERS | H23: =_xlfn.XLOOKUP(OWNED[[#This Row],[bgg_id]],library_data[bgg_id],library_data[mana_meeple_category])=OWNED[[#This Row],[category]] -> TRUE | I23: =COUNTIF(nzdesgn[NAME],OWNED[[#This Row],[bgg_name]]) -> 0
A24: Cathedral | B24: 7 | D24: =COUNTIF(OWNED[bgg_id],OWNED[[#This Row],[bgg_id]]) -> 1 | E24: =_xlfn.XLOOKUP(OWNED[[#This Row],[bgg_id]],bgg_cache[id],bgg_cache[title]) -> Cathedral | F24: =EXACT(OWNED[[#This Row],[name]],OWNED[[#This Row],[bgg_name]]) -> TRUE | G24: GATEWAY_STRATEGY | H24: =_xlfn.XLOOKUP(OWNED[[#This Row],[bgg_id]],library_data[bgg_id],library_data[mana_meeple_category])=OWNED[[#This Row],[category]] -> TRUE | I24: =COUNTIF(nzdesgn[NAME],OWNED[[#This Row],[bgg_name]]) -> 1
A25: Caverna: The Cave Farmers | B25: 102794 | D25: =COUNTIF(OWNED[bgg_id],OWNED[[#This Row],[bgg_id]]) -> 1 | E25: =_xlfn.XLOOKUP(OWNED[[#This Row],[bgg_id]],bgg_cache[id],bgg_cache[title]) -> Caverna: The Cave Farmers | F25: =EXACT(OWNED[[#This Row],[name]],OWNED[[#This Row],[bgg_name]]) -> TRUE | G25: CORE_STRATEGY | H25: =_xlfn.XLOOKUP(OWNED[[#This Row],[bgg_id]],library_data[bgg_id],library_data[mana_meeple_category])=OWNED[[#This Row],[category]] -> TRUE | I25: =COUNTIF(nzdesgn[NAME],OWNED[[#This Row],[bgg_name]]) -> 0
A26: Chronicles of Crime | B26: 239188 | D26: =COUNTIF(OWNED[bgg_id],OWNED[[#This Row],[bgg_id]]) -> 1 | E26: =_xlfn.XLOOKUP(OWNED[[#This Row],[bgg_id]],bgg_cache[id],bgg_cache[title]) -> Chronicles of Crime | F26: =EXACT(OWNED[[#This Row],[name]],OWNED[[#This Row],[bgg_name]]) -> TRUE | G26: COOP_ADVENTURE | H26: =_xlfn.XLOOKUP(OWNED[[#This Row],[bgg_id]],library_data[bgg_id],library_data[mana_meeple_category])=OWNED[[#This Row],[category]] -> TRUE | I26: =COUNTIF(nzdesgn[NAME],OWNED[[#This Row],[bgg_name]]) -> 0
A27: Citadels | B27: 205398 | D27: =COUNTIF(OWNED[bgg_id],OWNED[[#This Row],[bgg_id]]) -> 1 | E27: =_xlfn.XLOOKUP(OWNED[[#This Row],[bgg_id]],bgg_cache[id],bgg_cache[title]) -> Citadels | F27: =EXACT(OWNED[[#This Row],[name]],OWNED[[#This Row],[bgg_name]]) -> TRUE | G27: GATEWAY_STRATEGY | H27: =_xlfn.XLOOKUP(OWNED[[#This Row],[bgg_id]],library_data[bgg_id],library_data[mana_meeple_category])=OWNED[[#This Row],[category]] -> TRUE | I27: =COUNTIF(nzdesgn[NAME],OWNED[[#This Row],[bgg_name]]) -> 0
A28: Cockroach Soup | B28: 38391 | D28: =COUNTIF(OWNED[bgg_id],OWNED[[#This Row],[bgg_id]]) -> 1 | E28: =_xlfn.XLOOKUP(OWNED[[#This Row],[bgg_id]],bgg_cache[id],bgg_cache[title]) -> Kakerlakensuppe | F28: =EXACT(OWNED[[#This Row],[name]],OWNED[[#This Row],[bgg_name]]) -> FALSE | G28: KIDS_FAMILIES | H28: =_xlfn.XLOOKUP(OWNED[[#This Row],[bgg_id]],library_data[bgg_id],library_data[mana_meeple_category])=OWNED[[#This Row],[category]] -> TRUE | I28: =COUNTIF(nzdesgn[NAME],OWNED[[#This Row],[bgg_name]]) -> 0
A29: Codenames | B29: 178900 | D29: =COUNTIF(OWNED[bgg_id],OWNED[[#This Row],[bgg_id]]) -> 1 | E29: =_xlfn.XLOOKUP(OWNED[[#This Row],[bgg_id]],bgg_cache[id],bgg_cache[title]) -> Codenames | F29: =EXACT(OWNED[[#This Row],[name]],OWNED[[#This Row],[bgg_name]]) -> TRUE | G29: PARTY_ICEBREAKERS | H29: =_xlfn.XLOOKUP(OWNED[[#This Row],[bgg_id]],library_data[bgg_id],library_data[mana_meeple_category])=OWNED[[#This Row],[category]] -> TRUE | I29: =COUNTIF(nzdesgn[NAME],OWNED[[#This Row],[bgg_name]]) -> 0
A30: Coloretto | B30: 5782 | D30: =COUNTIF(OWNED[bgg_id],OWNED[[#This Row],[bgg_id]]) -> 1 | E30: =_xlfn.XLOOKUP(OWNED[[#This Row],[bgg_id]],bgg_cache[id],bgg_cache[title]) -> Coloretto | F30: =EXACT(OWNED[[#This Row],[name]],OWNED[[#This Row],[bgg_name]]) -> TRUE | G30: PARTY_ICEBREAKERS | H30: =_xlfn.XLOOKUP(OWNED[[#This Row],[bgg_id]],library_data[bgg_id],library_data[mana_meeple_category])=OWNED[[#This Row],[category]] -> TRUE | I30: =COUNTIF(nzdesgn[NAME],OWNED[[#This Row],[bgg_name]]) -> 0
A31: Concept | B31: 147151 | D31: =COUNTIF(OWNED[bgg_id],OWNED[[#This Row],[bgg_id]]) -> 1 | E31: =_xlfn.XLOOKUP(OWNED[[#This Row],[bgg_id]],bgg_cache[id],bgg_cache[title]) -> Concept | F31: =EXACT(OWNED[[#This Row],[name]],OWNED[[#This Row],[bgg_name]]) -> TRUE | G31: PARTY_ICEBREAKERS | H31: =_xlfn.XLOOKUP(OWNED[[#This Row],[bgg_id]],library_data[bgg_id],library_data[mana_meeple_category])=OWNED[[#This Row],[category]] -> TRUE | I31: =COUNTIF(nzdesgn[NAME],OWNED[[#This Row],[bgg_name]]) -> 0
A32: Cosmolancer | B32: 119 | D32: =COUNTIF(OWNED[bgg_id],OWNED[[#This Row],[bgg_id]]) -> 1 | E32: =_xlfn.XLOOKUP(OWNED[[#This Row],[bgg_id]],bgg_cache[id],bgg_cache[title]) -> Cosmolancer | F32: =EXACT(OWNED[[#This Row],[name]],OWNED[[#This Row],[bgg_name]]) -> TRUE | G32: PARTY_ICEBREAKERS | H32: =_xlfn.XLOOKUP(OWNED[[#This Row],[bgg_id]],library_data[bgg_id],library_data[mana_meeple_category])=OWNED[[#This Row],[category]] -> TRUE | I32: =COUNTIF(nzdesgn[NAME],OWNED[[#This Row],[bgg_name]]) -> 0
A33: Dead of Winter: A Crossroads Game | B33: 150376 | D33: =COUNTIF(OWNED[bgg_id],OWNED[[#This Row],[bgg_id]]) -> 1 | E33: =_xlfn.XLOOKUP(OWNED[[#This Row],[bgg_id]],bgg_cache[id],bgg_cache[title]) -> Dead of Winter: A Crossroads Game | F33: =EXACT(OWNED[[#This Row],[name]],OWNED[[#This Row],[bgg_name]]) -> TRUE | G33: COOP_ADVENTURE | H33: =_xlfn.XLOOKUP(OWNED[[#This Row],[bgg_id]],library_data[bgg_id],library_data[mana_meeple_category])=OWNED[[#This Row],[category]] -> TRUE | I33: =COUNTIF(nzdesgn[NAME],OWNED[[#This Row],[bgg_name]]) -> 0
A34: Dead of Winter: The Long Night | B34: 193037 | D34: =COUNTIF(OWNED[bgg_id],OWNED[[#This Row],[bgg_id]]) -> 1 | E34: =_xlfn.XLOOKUP(OWNED[[#This Row],[bgg_id]],bgg_cache[id],bgg_cache[title]) -> Dead of Winter: The Long Night | F34: =EXACT(OWNED[[#This Row],[name]],OWNED[[#This Row],[bgg_name]]) -> TRUE | G34: COOP_ADVENTURE | H34: =_xlfn.XLOOKUP(OWNED[[#This Row],[bgg_id]],library_data[bgg_id],library_data[mana_meeple_category])=OWNED[[#This Row],[category]] -> TRUE | I34: =COUNTIF(nzdesgn[NAME],OWNED[[#This Row],[bgg_name]]) -> 0
A35: Deception: Murder in Hong Kong | B35: 156129 | C35: 1 | D35: =COUNTIF(OWNED[bgg_id],OWNED[[#This Row],[bgg_id]]) -> 1 | E35: =_xlfn.XLOOKUP(OWNED[[#This Row],[bgg_id]],bgg_cache[id],bgg_cache[title]) -> Deception: Murder in Hong Kong | F35: =EXACT(OWNED[[#This Row],[name]],OWNED[[#This Row],[bgg_name]]) -> TRUE | G35: PARTY_ICEBREAKERS | H35: =_xlfn.XLOOKUP(OWNED[[#This Row],[bgg_id]],library_data[bgg_id],library_data[mana_meeple_category])=OWNED[[#This Row],[category]] -> TRUE | I35: =COUNTIF(nzdesgn[NAME],OWNED[[#This Row],[bgg_name]]) -> 0
A36: Decrypto | B36: 225694 | D36: =COUNTIF(OWNED[bgg_id],OWNED[[#This Row],[bgg_id]]) -> 1 | E36: =_xlfn.XLOOKUP(OWNED[[#This Row],[bgg_id]],bgg_cache[id],bgg_cache[title]) -> Decrypto | F36: =EXACT(OWNED[[#This Row],[name]],OWNED[[#This Row],[bgg_name]]) -> TRUE | G36: PARTY_ICEBREAKERS | H36: =_xlfn.XLOOKUP(OWNED[[#This Row],[bgg_id]],library_data[bgg_id],library_data[mana_meeple_category])=OWNED[[#This Row],[category]] -> TRUE | I36: =COUNTIF(nzdesgn[NAME],OWNED[[#This Row],[bgg_name]]) -> 0
A37: Descent: Legends of the Dark | B37: 322708 | D37: =COUNTIF(OWNED[bgg_id],OWNED[[#This Row],[bgg_id]]) -> 1 | E37: =_xlfn.XLOOKUP(OWNED[[#This Row],[bgg_id]],bgg_cache[id],bgg_cache[title]) -> Descent: Legends of the Dark | F37: =EXACT(OWNED[[#This Row],[name]],OWNED[[#This Row],[bgg_name]]) -> TRUE | G37: COOP_ADVENTURE | H37: =_xlfn.XLOOKUP(OWNED[[#This Row],[bgg_id]],library_data[bgg_id],library_data[mana_meeple_category])=OWNED[[#This Row],[category]] -> TRUE | I37: =COUNTIF(nzdesgn[NAME],OWNED[[#This Row],[bgg_name]]) -> 0
A38: Dinosaur World | B38: 317457 | C38: 1 | D38: =COUNTIF(OWNED[bgg_id],OWNED[[#This Row],[bgg_id]]) -> 1 | E38: =_xlfn.XLOOKUP(OWNED[[#This Row],[bgg_id]],bgg_cache[id],bgg_cache[title]) -> Dinosaur World | F38: =EXACT(OWNED[[#This Row],[name]],OWNED[[#This Row],[bgg_name]]) -> TRUE | G38: CORE_STRATEGY | H38: =_xlfn.XLOOKUP(OWNED[[#This Row],[bgg_id]],library_data[bgg_id],library_data[mana_meeple_category])=OWNED[[#This Row],[category]] -> TRUE | I38: =COUNTIF(nzdesgn[NAME],OWNED[[#This Row],[bgg_name]]) -> 0
A39: Dixit | B39: 39856 | D39: =COUNTIF(OWNED[bgg_id],OWNED[[#This Row],[bgg_id]]) -> 1 | E39: =_xlfn.XLOOKUP(OWNED[[#This Row],[bgg_id]],bgg_cache[id],bgg_cache[title]) -> Dixit | F39: =EXACT(OWNED[[#This Row],[name]],OWNED[[#This Row],[bgg_name]]) -> TRUE | G39: PARTY_ICEBREAKERS | H39: =_xlfn.XLOOKUP(OWNED[[#This Row],[bgg_id]],library_data[bgg_id],library_data[mana_meeple_category])=OWNED[[#This Row],[category]] -> TRUE | I39: =COUNTIF(nzdesgn[NAME],OWNED[[#This Row],[bgg_name]]) -> 0
A40: Dominion: Intrigue | B40: 40834 | D40: =COUNTIF(OWNED[bgg_id],OWNED[[#This Row],[bgg_id]]) -> 1 | E40: =_xlfn.XLOOKUP(OWNED[[#This Row],[bgg_id]],bgg_cache[id],bgg_cache[title]) -> Dominion: Intrigue | F40: =EXACT(OWNED[[#This Row],[name]],OWNED[[#This Row],[bgg_name]]) -> TRUE | G40: CORE_STRATEGY | H40: =_xlfn.XLOOKUP(OWNED[[#This Row],[bgg_id]],library_data[bgg_id],library_data[mana_meeple_category])=OWNED[[#This Row],[category]] -> TRUE | I40: =COUNTIF(nzdesgn[NAME],OWNED[[#This Row],[bgg_name]]) -> 0
...

Sheet BUY LIST
A1: RANK | B1: NAME | C1: Column1 | D1: BGG ID | E1: LPG_Status | F1: LPG_RRP | G1: Low | H1: Mean | I1: BEST | J1: Discount | K1: Delta | L1: QF | M1: STORE | N1: BGO LINK | O1: HAVE | P1: DUP
A2: 1 | B2: =IFERROR(_xlfn.XLOOKUP(BUYLIST10[[#This Row],[BGG ID]],bgg_cache[id],bgg_cache[title]),_xlfn.XLOOKUP(BUYLIST10[[#This Row],[BGG ID]],manual_bgg!B:B,manual_bgg!D:D)) -> Terraforming Mars | C2: =_xlfn.IMAGE(_xlfn.XLOOKUP(BUYLIST10[[#This Row],[BGG ID]],bgg_cache[id],bgg_cache[thumbnail_url]),,3,80) -> #VALUE! | D2: 167791 | E2: =_xlfn.XLOOKUP(BUYLIST10[[#This Row],[BGG ID]],STOREURL[BGG ID],STOREURL[STATUS]) -> AVAILABLE | F2: =_xlfn.XLOOKUP(BUYLIST10[[#This Row],[BGG ID]],STOREURL[BGG ID],STOREURL[LPG_RRP]) -> 179.99 | G2: =_xlfn.XLOOKUP(BUYLIST10[[#This Row],[NAME]],summary_prices[game],summary_prices[site_low_nzd]) -> 99 | H2: =_xlfn.XLOOKUP(BUYLIST10[[#This Row],[NAME]],summary_prices[game],summary_prices[site_mean_nzd]) -> 148.06 | I2: =_xlfn.XLOOKUP(BUYLIST10[[#This Row],[NAME]],summary_prices[game],summary_prices[best_in_stock_nzd]) -> 124.9 | J2: =IFERROR(_xlfn.XLOOKUP(BUYLIST10[[#This Row],[NAME]],summary_prices[game],summary_prices[discount_pct_vs_site_mean]),-99) -> 15.64 | K2: =_xlfn.XLOOKUP(BUYLIST10[[#This Row],[NAME]],summary_prices[game],summary_prices[delta_vs_site_disc_mean_pp]) -> -17.5 | L2: {=_xlfn.LET( _xlpm.b, BUYLIST10[[#This Row],[BEST]], _xlpm.s, BUYLIST10[[#This Row],[LPG_Status]], _xlpm.r, BUYLIST10[[#This Row],[LPG_RRP]], _xlpm.d, BUYLIST10[[#This Row],[Discount]], OR( AND( OR(_xlpm.s={"AVAILABLE","BACK_ORDER"}), IF(ISNUMBER(_xlpm.b), AND(_xlpm.b<>0, _xlpm.b*2<=_xlpm.r), FALSE) ), AND( OR(_xlpm.s={"NOT_FOUND","BACK_ORDER_OOS"}), _xlpm.d>30 ) ) )} -> FALSE | M2: =_xlfn.XLOOKUP(BUYLIST10[[#This Row],[NAME]],summary_prices[game],summary_prices[best_in_stock_store]) -> Vagabond | N2: =HYPERLINK(_xlfn.XLOOKUP(BUYLIST10[[#This Row],[BGG ID]],STOREURL[BGG ID],STOREURL[BGO LINK])) -> https://www.boardgameoracle.com/en-NZ/boardgame/price/DJXkZt9Z_z/terraforming-mars | O2: =COUNTIF(OWNED[bgg_id],BUYLIST10[[#This Row],[BGG ID]]) -> 0 | P2: =COUNTIF(BUYLIST10[NAME],BUYLIST10[[#This Row],[NAME]]) -> 1
A3: 2 | B3: =IFERROR(_xlfn.XLOOKUP(BUYLIST10[[#This Row],[BGG ID]],bgg_cache[id],bgg_cache[title]),_xlfn.XLOOKUP(BUYLIST10[[#This Row],[BGG ID]],manual_bgg!B:B,manual_bgg!D:D)) -> Ark Nova | C3: =_xlfn.IMAGE(_xlfn.XLOOKUP(BUYLIST10[[#This Row],[BGG ID]],bgg_cache[id],bgg_cache[thumbnail_url]),,3,80) -> #VALUE! | D3: 342942 | E3: =_xlfn.XLOOKUP(BUYLIST10[[#This Row],[BGG ID]],STOREURL[BGG ID],STOREURL[STATUS]) -> AVAILABLE | F3: =_xlfn.XLOOKUP(BUYLIST10[[#This Row],[BGG ID]],STOREURL[BGG ID],STOREURL[LPG_RRP]) -> 164.99 | G3: =_xlfn.XLOOKUP(BUYLIST10[[#This Row],[NAME]],summary_prices[game],summary_prices[site_low_nzd]) -> 98 | H3: =_xlfn.XLOOKUP(BUYLIST10[[#This Row],[NAME]],summary_prices[game],summary_prices[site_mean_nzd]) -> 152.01 | I3: =_xlfn.XLOOKUP(BUYLIST10[[#This Row],[NAME]],summary_prices[game],summary_prices[best_in_stock_nzd]) -> 98 | J3: =IFERROR(_xlfn.XLOOKUP(BUYLIST10[[#This Row],[NAME]],summary_prices[game],summary_prices[discount_pct_vs_site_mean]),-99) -> 35.53 | K3: =_xlfn.XLOOKUP(BUYLIST10[[#This Row],[NAME]],summary_prices[game],summary_prices[delta_vs_site_disc_mean_pp]) -> 0 | L3: {=_xlfn.LET( _xlpm.b, BUYLIST10[[#This Row],[BEST]], _xlpm.s, BUYLIST10[[#This Row],[LPG_Status]], _xlpm.r, BUYLIST10[[#This Row],[LPG_RRP]], _xlpm.d, BUYLIST10[[#This Row],[Discount]], OR( AND( OR(_xlpm.s={"AVAILABLE","BACK_ORDER"}), IF(ISNUMBER(_xlpm.b), AND(_xlpm.b<>0, _xlpm.b*2<=_xlpm.r), FALSE) ), AND( OR(_xlpm.s={"NOT_FOUND","BACK_ORDER_OOS"}), _xlpm.d>30 ) ) )} -> FALSE | M3: =_xlfn.XLOOKUP(BUYLIST10[[#This Row],[NAME]],summary_prices[game],summary_prices[best_in_stock_store]) -> EB Games NZ | N3: =HYPERLINK(_xlfn.XLOOKUP(BUYLIST10[[#This Row],[BGG ID]],STOREURL[BGG ID],STOREURL[BGO LINK])) -> https://www.boardgameoracle.com/en-NZ/boardgame/price/yKEg3oOK67/ark-nova | O3: =COUNTIF(OWNED[bgg_id],BUYLIST10[[#This Row],[BGG ID]]) -> 0 | P3: =COUNTIF(BUYLIST10[NAME],BUYLIST10[[#This Row],[NAME]]) -> 1
A4: 3 | B4: =IFERROR(_xlfn.XLOOKUP(BUYLIST10[[#This Row],[BGG ID]],bgg_cache[id],bgg_cache[title]),_xlfn.XLOOKUP(BUYLIST10[[#This Row],[BGG ID]],manual_bgg!B:B,manual_bgg!D:D)) -> Dune: Imperium – Uprising | C4: =_xlfn.IMAGE(_xlfn.XLOOKUP(BUYLIST10[[#This Row],[BGG ID]],bgg_cache[id],bgg_cache[thumbnail_url]),,3,80) -> #VALUE! | D4: 397598 | E4: =_xlfn.XLOOKUP(BUYLIST10[[#This Row],[BGG ID]],STOREURL[BGG ID],STOREURL[STATUS]) -> AVAILABLE | F4: =_xlfn.XLOOKUP(BUYLIST10[[#This Row],[BGG ID]],STOREURL[BGG ID],STOREURL[LPG_RRP]) -> 134.99 | G4: =_xlfn.XLOOKUP(BUYLIST10[[#This Row],[NAME]],summary_prices[game],summary_prices[site_low_nzd]) -> 108.47 | H4: =_xlfn.XLOOKUP(BUYLIST10[[#This Row],[NAME]],summary_prices[game],summary_prices[site_mean_nzd]) -> 129.56 | I4: =_xlfn.XLOOKUP(BUYLIST10[[#This Row],[NAME]],summary_prices[game],summary_prices[best_in_stock_nzd]) -> 109.1 | J4: =IFERROR(_xlfn.XLOOKUP(BUYLIST10[[#This Row],[NAME]],summary_prices[game],summary_prices[discount_pct_vs_site_mean]),-99) -> 15.79 | K4: =_xlfn.XLOOKUP(BUYLIST10[[#This Row],[NAME]],summary_prices[game],summary_prices[delta_vs_site_disc_mean_pp]) -> -0.49 | L4: {=_xlfn.LET( _xlpm.b, BUYLIST10[[#This Row],[BEST]], _xlpm.s, BUYLIST10[[#This Row],[LPG_Status]], _xlpm.r, BUYLIST10[[#This Row],[LPG_RRP]], _xlpm.d, BUYLIST10[[#This Row],[Discount]], OR( AND( OR(_xlpm.s={"AVAILABLE","BACK_ORDER"}), IF(ISNUMBER(_xlpm.b), AND(_xlpm.b<>0, _xlpm.b*2<=_xlpm.r), FALSE) ), AND( OR(_xlpm.s={"NOT_FOUND","BACK_ORDER_OOS"}), _xlpm.d>30 ) ) )} -> FALSE | M4: =_xlfn.XLOOKUP(BUYLIST10[[#This Row],[NAME]],summary_prices[game],summary_prices[best_in_stock_store]) -> Gameology | N4: =HYPERLINK(_xlfn.XLOOKUP(BUYLIST10[[#This Row],[BGG ID]],STOREURL[BGG ID],STOREURL[BGO LINK])) -> https://www.boardgameoracle.com/en-NZ/boardgame/price/NfBhb2GnXh/dune-imperium-uprising | O4: =COUNTIF(OWNED[bgg_id],BUYLIST10[[#This Row],[BGG ID]]) -> 0 | P4: =COUNTIF(BUYLIST10[NAME],BUYLIST10[[#This Row],[NAME]]) -> 1
A5: 4 | B5: =IFERROR(_xlfn.XLOOKUP(BUYLIST10[[#This Row],[BGG ID]],bgg_cache[id],bgg_cache[title]),_xlfn.XLOOKUP(BUYLIST10[[#This Row],[BGG ID]],manual_bgg!B:B,manual_bgg!D:D)) -> Brass: Birmingham | C5: =_xlfn.IMAGE(_xlfn.XLOOKUP(BUYLIST10[[#This Row],[BGG ID]],bgg_cache[id],bgg_cache[thumbnail_url]),,3,80) -> #VALUE! | D5: 224517 | E5: =_xlfn.XLOOKUP(BUYLIST10[[#This Row],[BGG ID]],STOREURL[BGG ID],STOREURL[STATUS]) -> AVAILABLE | F5: =_xlfn.XLOOKUP(BUYLIST10[[#This Row],[BGG ID]],STOREURL[BGG ID],STOREURL[LPG_RRP]) -> 179.99 | G5: =_xlfn.XLOOKUP(BUYLIST10[[#This Row],[NAME]],summary_prices[game],summary_prices[site_low_nzd]) -> 110 | H5: =_xlfn.XLOOKUP(BUYLIST10[[#This Row],[NAME]],summary_prices[game],summary_prices[site_mean_nzd]) -> 167.53 | I5: =_xlfn.XLOOKUP(BUYLIST10[[#This Row],[NAME]],summary_prices[game],summary_prices[best_in_stock_nzd]) -> 137.99 | J5: =IFERROR(_xlfn.XLOOKUP(BUYLIST10[[#This Row],[NAME]],summary_prices[game],summary_prices[discount_pct_vs_site_mean]),-99) -> 17.63 | K5: =_xlfn.XLOOKUP(BUYLIST10[[#This Row],[NAME]],summary_prices[game],summary_prices[delta_vs_site_disc_mean_pp]) -> -16.71 | L5: {=_xlfn.LET( _xlpm.b, BUYLIST10[[#This Row],[BEST]], _xlpm.s, BUYLIST10[[#This Row],[LPG_Status]], _xlpm.r, BUYLIST10[[#This Row],[LPG_RRP]], _xlpm.d, BUYLIST10[[#This Row],[Discount]], OR( AND( OR(_xlpm.s={"AVAILABLE","BACK_ORDER"}), IF(ISNUMBER(_xlpm.b), AND(_xlpm.b<>0, _xlpm.b*2<=_xlpm.r), FALSE) ), AND( OR(_xlpm.s={"NOT_FOUND","BACK_ORDER_OOS"}), _xlpm.d>30 ) ) )} -> FALSE | M5: =_xlfn.XLOOKUP(BUYLIST10[[#This Row],[NAME]],summary_prices[game],summary_prices[best_in_stock_store]) -> The Board Gamer NZ | N5: =HYPERLINK(_xlfn.XLOOKUP(BUYLIST10[[#This Row],[BGG ID]],STOREURL[BGG ID],STOREURL[BGO LINK])) -> https://www.boardgameoracle.com/en-NZ/boardgame/price/K2tNPgSWOC/brass-birmingham | O5: =COUNTIF(OWNED[bgg_id],BUYLIST10[[#This Row],[BGG ID]]) -> 0 | P5: =COUNTIF(BUYLIST10[NAME],BUYLIST10[[#This Row],[NAME]]) -> 1
A6: 5 | B6: =IFERROR(_xlfn.XLOOKUP(BUYLIST10[[#This Row],[BGG ID]],bgg_cache[id],bgg_cache[title]),_xlfn.XLOOKUP(BUYLIST10[[#This Row],[BGG ID]],manual_bgg!B:B,manual_bgg!D:D)) -> Spirit Island | C6: =_xlfn.IMAGE(_xlfn.XLOOKUP(BUYLIST10[[#This Row],[BGG ID]],bgg_cache[id],bgg_cache[thumbnail_url]),,3,80) -> #VALUE! | D6: 162886 | E6: =_xlfn.XLOOKUP(BUYLIST10[[#This Row],[BGG ID]],STOREURL[BGG ID],STOREURL[STATUS]) -> AVAILABLE | F6: =_xlfn.XLOOKUP(BUYLIST10[[#This Row],[BGG ID]],STOREURL[BGG ID],STOREURL[LPG_RRP]) -> 194.99 | G6: =_xlfn.XLOOKUP(BUYLIST10[[#This Row],[NAME]],summary_prices[game],summary_prices[site_low_nzd]) -> 142.75 | H6: =_xlfn.XLOOKUP(BUYLIST10[[#This Row],[NAME]],summary_prices[game],summary_prices[site_mean_nzd]) -> 183.72 | I6: =_xlfn.XLOOKUP(BUYLIST10[[#This Row],[NAME]],summary_prices[game],summary_prices[best_in_stock_nzd]) -> 143.57 | J6: =IFERROR(_xlfn.XLOOKUP(BUYLIST10[[#This Row],[NAME]],summary_prices[game],summary_prices[discount_pct_vs_site_mean]),-99) -> 21.85 | K6: =_xlfn.XLOOKUP(BUYLIST10[[#This Row],[NAME]],summary_prices[game],summary_prices[delta_vs_site_disc_mean_pp]) -> -0.45 | L6: {=_xlfn.LET( _xlpm.b, BUYLIST10[[#This Row],[BEST]], _xlpm.s, BUYLIST10[[#This Row],[LPG_Status]], _xlpm.r, BUYLIST10[[#This Row],[LPG_RRP]], _xlpm.d, BUYLIST10[[#This Row],[Discount]], OR( AND( OR(_xlpm.s={"AVAILABLE","BACK_ORDER"}), IF(ISNUMBER(_xlpm.b), AND(_xlpm.b<>0, _xlpm.b*2<=_xlpm.r), FALSE) ), AND( OR(_xlpm.s={"NOT_FOUND","BACK_ORDER_OOS"}), _xlpm.d>30 ) ) )} -> FALSE | M6: =_xlfn.XLOOKUP(BUYLIST10[[#This Row],[NAME]],summary_prices[game],summary_prices[best_in_stock_store]) -> Gameology | N6: =HYPERLINK(_xlfn.XLOOKUP(BUYLIST10[[#This Row],[BGG ID]],STOREURL[BGG ID],STOREURL[BGO LINK])) -> https://www.boardgameoracle.com/en-NZ/boardgame/price/dqzBAt2yEb/spirit-island | O6: =COUNTIF(OWNED[bgg_id],BUYLIST10[[#This Row],[BGG ID]]) -> 0 | P6: =COUNTIF(BUYLIST10[NAME],BUYLIST10[[#This Row],[NAME]]) -> 1
A7: 6 | B7: =IFERROR(_xlfn.XLOOKUP(BUYLIST10[[#This Row],[BGG ID]],bgg_cache[id],bgg_cache[title]),_xlfn.XLOOKUP(BUYLIST10[[#This Row],[BGG ID]],manual_bgg!B:B,manual_bgg!D:D)) -> Concordia | C7: =_xlfn.IMAGE(_xlfn.XLOOKUP(BUYLIST10[[#This Row],[BGG ID]],bgg_cache[id],bgg_cache[thumbnail_url]),,3,80) -> #VALUE! | D7: 124361 | E7: =_xlfn.XLOOKUP(BUYLIST10[[#This Row],[BGG ID]],STOREURL[BGG ID],STOREURL[STATUS]) -> AVAILABLE | F7: =_xlfn.XLOOKUP(BUYLIST10[[#This Row],[BGG ID]],STOREURL[BGG ID],STOREURL[LPG_RRP]) -> 144.99 | G7: =_xlfn.XLOOKUP(BUYLIST10[[#This Row],[NAME]],summary_prices[game],summary_prices[site_low_nzd]) -> 110.12 | H7: =_xlfn.XLOOKUP(BUYLIST10[[#This Row],[NAME]],summary_prices[game],summary_prices[site_mean_nzd]) -> 129.75 | I7: =_xlfn.XLOOKUP(BUYLIST10[[#This Row],[NAME]],summary_prices[game],summary_prices[best_in_stock_nzd]) -> 110.87 | J7: =IFERROR(_xlfn.XLOOKUP(BUYLIST10[[#This Row],[NAME]],summary_prices[game],summary_prices[discount_pct_vs_site_mean]),-99) -> 14.55 | K7: =_xlfn.XLOOKUP(BUYLIST10[[#This Row],[NAME]],summary_prices[game],summary_prices[delta_vs_site_disc_mean_pp]) -> -0.58 | L7: {=_xlfn.LET( _xlpm.b, BUYLIST10[[#This Row],[BEST]], _xlpm.s, BUYLIST10[[#This Row],[LPG_Status]], _xlpm.r, BUYLIST10[[#This Row],[LPG_RRP]], _xlpm.d, BUYLIST10[[#This Row],[Discount]], OR( AND( OR(_xlpm.s={"AVAILABLE","BACK_ORDER"}), IF(ISNUMBER(_xlpm.b), AND(_xlpm.b<>0, _xlpm.b*2<=_xlpm.r), FALSE) ), AND( OR(_xlpm.s={"NOT_FOUND","BACK_ORDER_OOS"}), _xlpm.d>30 ) ) )} -> FALSE | M7: =_xlfn.XLOOKUP(BUYLIST10[[#This Row],[NAME]],summary_prices[game],summary_prices[best_in_stock_store]) -> Amazon AU | N7: =HYPERLINK(_xlfn.XLOOKUP(BUYLIST10[[#This Row],[BGG ID]],STOREURL[BGG ID],STOREURL[BGO LINK])) -> https://www.boardgameoracle.com/en-NZ/boardgame/price/lWFkM-ljpv/concordia | O7: =COUNTIF(OWNED[bgg_id],BUYLIST10[[#This Row],[BGG ID]]) -> 0 | P7: =COUNTIF(BUYLIST10[NAME],BUYLIST10[[#This Row],[NAME]]) -> 1
A8: 7 | B8: =IFERROR(_xlfn.XLOOKUP(BUYLIST10[[#This Row],[BGG ID]],bgg_cache[id],bgg_cache[title]),_xlfn.XLOOKUP(BUYLIST10[[#This Row],[BGG ID]],manual_bgg!B:B,manual_bgg!D:D)) -> Great Western Trail: New Zealand | C8: =_xlfn.IMAGE(_xlfn.XLOOKUP(BUYLIST10[[#This Row],[BGG ID]],bgg_cache[id],bgg_cache[thumbnail_url]),,3,80) -> #VALUE! | D8: 380607 | E8: =_xlfn.XLOOKUP(BUYLIST10[[#This Row],[BGG ID]],STOREURL[BGG ID],STOREURL[STATUS]) -> NOT_FOUND | F8: =_xlfn.XLOOKUP(BUYLIST10[[#This Row],[BGG ID]],STOREURL[BGG ID],STOREURL[LPG_RRP]) -> 0 | G8: =_xlfn.XLOOKUP(BUYLIST10[[#This Row],[NAME]],summary_prices[game],summary_prices[site_low_nzd]) -> 101.25 | H8: =_xlfn.XLOOKUP(BUYLIST10[[#This Row],[NAME]],summary_prices[game],summary_prices[site_mean_nzd]) -> 137.73 | I8: =_xlfn.XLOOKUP(BUYLIST10[[#This Row],[NAME]],summary_prices[game],summary_prices[best_in_stock_nzd]) -> 120.59 | J8: =IFERROR(_xlfn.XLOOKUP(BUYLIST10[[#This Row],[NAME]],summary_prices[game],summary_prices[discount_pct_vs_site_mean]),-99) -> 12.44 | K8: =_xlfn.XLOOKUP(BUYLIST10[[#This Row],[NAME]],summary_prices[game],summary_prices[delta_vs_site_disc_mean_pp]) -> -14.04 | L8: {=_xlfn.LET( _xlpm.b, BUYLIST10[[#This Row],[BEST]], _xlpm.s, BUYLIST10[[#This Row],[LPG_Status]], _xlpm.r, BUYLIST10[[#This Row],[LPG_RRP]], _xlpm.d, BUYLIST10[[#This Row],[Discount]], OR( AND( OR(_xlpm.s={"AVAILABLE","BACK_ORDER"}), IF(ISNUMBER(_xlpm.b), AND(_xlpm.b<>0, _xlpm.b*2<=_xlpm.r), FALSE) ), AND( OR(_xlpm.s={"NOT_FOUND","BACK_ORDER_OOS"}), _xlpm.d>30 ) ) )} -> FALSE | M8: =_xlfn.XLOOKUP(BUYLIST10[[#This Row],[NAME]],summary_prices[game],summary_prices[best_in_stock_store]) -> Gameology | N8: =HYPERLINK(_xlfn.XLOOKUP(BUYLIST10[[#This Row],[BGG ID]],STOREURL[BGG ID],STOREURL[BGO LINK])) -> https://www.boardgameoracle.com/en-NZ/boardgame/price/pDrG0cjAJY/great-western-trail-new-zealand | O8: =COUNTIF(OWNED[bgg_id],BUYLIST10[[#This Row],[BGG ID]]) -> 0 | P8: =COUNTIF(BUYLIST10[NAME],BUYLIST10[[#This Row],[NAME]]) -> 1
A9: 8 | B9: =IFERROR(_xlfn.XLOOKUP(BUYLIST10[[#This Row],[BGG ID]],bgg_cache[id],bgg_cache[title]),_xlfn.XLOOKUP(BUYLIST10[[#This Row],[BGG ID]],manual_bgg!B:B,manual_bgg!D:D)) -> Quacks | C9: =_xlfn.IMAGE(_xlfn.XLOOKUP(BUYLIST10[[#This Row],[BGG ID]],bgg_cache[id],bgg_cache[thumbnail_url]),,3,80) -> #VALUE! | D9: 244521 | E9: =_xlfn.XLOOKUP(BUYLIST10[[#This Row],[BGG ID]],STOREURL[BGG ID],STOREURL[STATUS]) -> AVAILABLE | F9: =_xlfn.XLOOKUP(BUYLIST10[[#This Row],[BGG ID]],STOREURL[BGG ID],STOREURL[LPG_RRP]) -> 139.99 | G9: =_xlfn.XLOOKUP(BUYLIST10[[#This Row],[NAME]],summary_prices[game],summary_prices[site_low_nzd]) -> 79 | H9: =_xlfn.XLOOKUP(BUYLIST10[[#This Row],[NAME]],summary_prices[game],summary_prices[site_mean_nzd]) -> 95.66 | I9: =_xlfn.XLOOKUP(BUYLIST10[[#This Row],[NAME]],summary_prices[game],summary_prices[best_in_stock_nzd]) -> 80.37 | J9: =IFERROR(_xlfn.XLOOKUP(BUYLIST10[[#This Row],[NAME]],summary_prices[game],summary_prices[discount_pct_vs_site_mean]),-99) -> 15.98 | K9: =_xlfn.XLOOKUP(BUYLIST10[[#This Row],[NAME]],summary_prices[game],summary_prices[delta_vs_site_disc_mean_pp]) -> -1.43 | L9: {=_xlfn.LET( _xlpm.b, BUYLIST10[[#This Row],[BEST]], _xlpm.s, BUYLIST10[[#This Row],[LPG_Status]], _xlpm.r, BUYLIST10[[#This Row],[LPG_RRP]], _xlpm.d, BUYLIST10[[#This Row],[Discount]], OR( AND( OR(_xlpm.s={"AVAILABLE","BACK_ORDER"}), IF(ISNUMBER(_xlpm.b), AND(_xlpm.b<>0, _xlpm.b*2<=_xlpm.r), FALSE) ), AND( OR(_xlpm.s={"NOT_FOUND","BACK_ORDER_OOS"}), _xlpm.d>30 ) ) )} -> FALSE | M9: =_xlfn.XLOOKUP(BUYLIST10[[#This Row],[NAME]],summary_prices[game],summary_prices[best_in_stock_store]) -> Gameology | N9: =HYPERLINK(_xlfn.XLOOKUP(BUYLIST10[[#This Row],[BGG ID]],STOREURL[BGG ID],STOREURL[BGO LINK])) -> https://www.boardgameoracle.com/en-NZ/boardgame/price/bD0EsHvlcZ/quacks | O9: =COUNTIF(OWNED[bgg_id],BUYLIST10[[#This Row],[BGG ID]]) -> 0 | P9: =COUNTIF(BUYLIST10[NAME],BUYLIST10[[#This Row],[NAME]]) -> 1
A10: 9 | B10: =IFERROR(_xlfn.XLOOKUP(BUYLIST10[[#This Row],[BGG ID]],bgg_cache[id],bgg_cache[title]),_xlfn.XLOOKUP(BUYLIST10[[#This Row],[BGG ID]],manual_bgg!B:B,manual_bgg!D:D)) -> Everdell | C10: =_xlfn.IMAGE(_xlfn.XLOOKUP(BUYLIST10[[#This Row],[BGG ID]],bgg_cache[id],bgg_cache[thumbnail_url]),,3,80) -> #VALUE! | D10: 199792 | E10: =_xlfn.XLOOKUP(BUYLIST10[[#This Row],[BGG ID]],STOREURL[BGG ID],STOREURL[STATUS]) -> AVAILABLE | F10: =_xlfn.XLOOKUP(BUYLIST10[[#This Row],[BGG ID]],STOREURL[BGG ID],STOREURL[LPG_RRP]) -> 159.99 | G10: =_xlfn.XLOOKUP(BUYLIST10[[#This Row],[NAME]],summary_prices[game],summary_prices[site_low_nzd]) -> 95.76 | H10: =_xlfn.XLOOKUP(BUYLIST10[[#This Row],[NAME]],summary_prices[game],summary_prices[site_mean_nzd]) -> 136.37 | I10: =_xlfn.XLOOKUP(BUYLIST10[[#This Row],[NAME]],summary_prices[game],summary_prices[best_in_stock_nzd]) -> 114.27 | J10: =IFERROR(_xlfn.XLOOKUP(BUYLIST10[[#This Row],[NAME]],summary_prices[game],summary_prices[discount_pct_vs_site_mean]),-99) -> 16.21 | K10: =_xlfn.XLOOKUP(BUYLIST10[[#This Row],[NAME]],summary_prices[game],summary_prices[delta_vs_site_disc_mean_pp]) -> -13.57 | L10: {=_xlfn.LET( _xlpm.b, BUYLIST10[[#This Row],[BEST]], _xlpm.s, BUYLIST10[[#This Row],[LPG_Status]], _xlpm.r, BUYLIST10[[#This Row],[LPG_RRP]], _xlpm.d, BUYLIST10[[#This Row],[Discount]], OR( AND( OR(_xlpm.s={"AVAILABLE","BACK_ORDER"}), IF(ISNUMBER(_xlpm.b), AND(_xlpm.b<>0, _xlpm.b*2<=_xlpm.r), FALSE) ), AND( OR(_xlpm.s={"NOT_FOUND","BACK_ORDER_OOS"}), _xlpm.d>30 ) ) )} -> FALSE | M10: =_xlfn.XLOOKUP(BUYLIST10[[#This Row],[NAME]],summary_prices[game],summary_prices[best_in_stock_store]) -> Gameology | N10: =HYPERLINK(_xlfn.XLOOKUP(BUYLIST10[[#This Row],[BGG ID]],STOREURL[BGG ID],STOREURL[BGO LINK])) -> https://www.boardgameoracle.com/en-NZ/boardgame/price/vhcYsCqPMP/everdell | O10: =COUNTIF(OWNED[bgg_id],BUYLIST10[[#This Row],[BGG ID]]) -> 0 | P10: =COUNTIF(BUYLIST10[NAME],BUYLIST10[[#This Row],[NAME]]) -> 1
A11: 10 | B11: =IFERROR(_xlfn.XLOOKUP(BUYLIST10[[#This Row],[BGG ID]],bgg_cache[id],bgg_cache[title]),_xlfn.XLOOKUP(BUYLIST10[[#This Row],[BGG ID]],manual_bgg!B:B,manual_bgg!D:D)) -> Clank!: A Deck-Building Adventure | C11: =_xlfn.IMAGE(_xlfn.XLOOKUP(BUYLIST10[[#This Row],[BGG ID]],bgg_cache[id],bgg_cache[thumbnail_url]),,3,80) -> #VALUE! | D11: 201808 | E11: =_xlfn.XLOOKUP(BUYLIST10[[#This Row],[BGG ID]],STOREURL[BGG ID],STOREURL[STATUS]) -> AVAILABLE | F11: =_xlfn.XLOOKUP(BUYLIST10[[#This Row],[BGG ID]],STOREURL[BGG ID],STOREURL[LPG_RRP]) -> 134.99 | G11: =_xlfn.XLOOKUP(BUYLIST10[[#This Row],[NAME]],summary_prices[game],summary_prices[site_low_nzd]) -> #N/A | H11: =_xlfn.XLOOKUP(BUYLIST10[[#This Row],[NAME]],summary_prices[game],summary_prices[site_mean_nzd]) -> #N/A | I11: =_xlfn.XLOOKUP(BUYLIST10[[#This Row],[NAME]],summary_prices[game],summary_prices[best_in_stock_nzd]) -> #N/A | J11: =IFERROR(_xlfn.XLOOKUP(BUYLIST10[[#This Row],[NAME]],summary_prices[game],summary_prices[discount_pct_vs_site_mean]),-99) -> -99 | K11: =_xlfn.XLOOKUP(BUYLIST10[[#This Row],[NAME]],summary_prices[game],summary_prices[delta_vs_site_disc_mean_pp]) -> #N/A | L11: {=_xlfn.LET( _xlpm.b, BUYLIST10[[#This Row],[BEST]], _xlpm.s, BUYLIST10[[#This Row],[LPG_Status]], _xlpm.r, BUYLIST10[[#This Row],[LPG_RRP]], _xlpm.d, BUYLIST10[[#This Row],[Discount]], OR( AND( OR(_xlpm.s={"AVAILABLE","BACK_ORDER"}), IF(ISNUMBER(_xlpm.b), AND(_xlpm.b<>0, _xlpm.b*2<=_xlpm.r), FALSE) ), AND( OR(_xlpm.s={"NOT_FOUND","BACK_ORDER_OOS"}), _xlpm.d>30 ) ) )} -> FALSE | M11: =_xlfn.XLOOKUP(BUYLIST10[[#This Row],[NAME]],summary_prices[game],summary_prices[best_in_stock_store]) -> #N/A | N11: =HYPERLINK(_xlfn.XLOOKUP(BUYLIST10[[#This Row],[BGG ID]],STOREURL[BGG ID],STOREURL[BGO LINK])) -> https://www.boardgameoracle.com/en-NZ/boardgame/price/455SQydqa0/clank-a-deck-building-adventure | O11: =COUNTIF(OWNED[bgg_id],BUYLIST10[[#This Row],[BGG ID]]) -> 0 | P11: =COUNTIF(BUYLIST10[NAME],BUYLIST10[[#This Row],[NAME]]) -> 1
A12: 11 | B12: =IFERROR(_xlfn.XLOOKUP(BUYLIST10[[#This Row],[BGG ID]],bgg_cache[id],bgg_cache[title]),_xlfn.XLOOKUP(BUYLIST10[[#This Row],[BGG ID]],manual_bgg!B:B,manual_bgg!D:D)) -> The Quest for El Dorado | C12: =_xlfn.IMAGE(_xlfn.XLOOKUP(BUYLIST10[[#This Row],[BGG ID]],bgg_cache[id],bgg_cache[thumbnail_url]),,3,80) -> #N/A | D12: 217372 | E12: =_xlfn.XLOOKUP(BUYLIST10[[#This Row],[BGG ID]],STOREURL[BGG ID],STOREURL[STATUS]) -> NOT_FOUND | F12: =_xlfn.XLOOKUP(BUYLIST10[[#This Row],[BGG ID]],STOREURL[BGG ID],STOREURL[LPG_RRP]) -> 0 | G12: =_xlfn.XLOOKUP(BUYLIST10[[#This Row],[NAME]],summary_prices[game],summary_prices[site_low_nzd]) -> 78.77 | H12: =_xlfn.XLOOKUP(BUYLIST10[[#This Row],[NAME]],summary_prices[game],summary_prices[site_mean_nzd]) -> 80.56 | I12: =_xlfn.XLOOKUP(BUYLIST10[[#This Row],[NAME]],summary_prices[game],summary_prices[best_in_stock_nzd]) -> 79.22 | J12: =IFERROR(_xlfn.XLOOKUP(BUYLIST10[[#This Row],[NAME]],summary_prices[game],summary_prices[discount_pct_vs_site_mean]),-99) -> 1.66 | K12: =_xlfn.XLOOKUP(BUYLIST10[[#This Row],[NAME]],summary_prices[game],summary_prices[delta_vs_site_disc_mean_pp]) -> -0.56 | L12: {=_xlfn.LET( _xlpm.b, BUYLIST10[[#This Row],[BEST]], _xlpm.s, BUYLIST10[[#This Row],[LPG_Status]], _xlpm.r, BUYLIST10[[#This Row],[LPG_RRP]], _xlpm.d, BUYLIST10[[#This Row],[Discount]], OR( AND( OR(_xlpm.s={"AVAILABLE","BACK_ORDER"}), IF(ISNUMBER(_xlpm.b), AND(_xlpm.b<>0, _xlpm.b*2<=_xlpm.r), FALSE) ), AND( OR(_xlpm.s={"NOT_FOUND","BACK_ORDER_OOS"}), _xlpm.d>30 ) ) )} -> FALSE | M12: =_xlfn.XLOOKUP(BUYLIST10[[#This Row],[NAME]],summary_prices[game],summary_prices[best_in_stock_store]) -> Gameology | N12: =HYPERLINK(_xlfn.XLOOKUP(BUYLIST10[[#This Row],[BGG ID]],STOREURL[BGG ID],STOREURL[BGO LINK])) -> https://www.boardgameoracle.com/en-NZ/boardgame/price/ZZsrjOqQFe/the-quest-for-el-dorado | O12: =COUNTIF(OWNED[bgg_id],BUYLIST10[[#This Row],[BGG ID]]) -> 0 | P12: =COUNTIF(BUYLIST10[NAME],BUYLIST10[[#This Row],[NAME]]) -> 1
A13: 12 | B13: =IFERROR(_xlfn.XLOOKUP(BUYLIST10[[#This Row],[BGG ID]],bgg_cache[id],bgg_cache[title]),_xlfn.XLOOKUP(BUYLIST10[[#This Row],[BGG ID]],manual_bgg!B:B,manual_bgg!D:D)) -> Orléans | C13: =_xlfn.IMAGE(_xlfn.XLOOKUP(BUYLIST10[[#This Row],[BGG ID]],bgg_cache[id],bgg_cache[thumbnail_url]),,3,80) -> #VALUE! | D13: 164928 | E13: =_xlfn.XLOOKUP(BUYLIST10[[#This Row],[BGG ID]],STOREURL[BGG ID],STOREURL[STATUS]) -> BACK_ORDER_OOS | F13: =_xlfn.XLOOKUP(BUYLIST10[[#This Row],[BGG ID]],STOREURL[BGG ID],STOREURL[LPG_RRP]) -> 124.99 | G13: =_xlfn.XLOOKUP(BUYLIST10[[#This Row],[NAME]],summary_prices[game],summary_prices[site_low_nzd]) -> 68.49 | H13: =_xlfn.XLOOKUP(BUYLIST10[[#This Row],[NAME]],summary_prices[game],summary_prices[site_mean_nzd]) -> 106.19 | I13: =_xlfn.XLOOKUP(BUYLIST10[[#This Row],[NAME]],summary_prices[game],summary_prices[best_in_stock_nzd]) -> 68.88 | J13: =IFERROR(_xlfn.XLOOKUP(BUYLIST10[[#This Row],[NAME]],summary_prices[game],summary_prices[discount_pct_vs_site_mean]),-99) -> 35.14 | K13: =_xlfn.XLOOKUP(BUYLIST10[[#This Row],[NAME]],summary_prices[game],summary_prices[delta_vs_site_disc_mean_pp]) -> -0.36 | L13: {=_xlfn.LET( _xlpm.b, BUYLIST10[[#This Row],[BEST]], _xlpm.s, BUYLIST10[[#This Row],[LPG_Status]], _xlpm.r, BUYLIST10[[#This Row],[LPG_RRP]], _xlpm.d, BUYLIST10[[#This Row],[Discount]], OR( AND( OR(_xlpm.s={"AVAILABLE","BACK_ORDER"}), IF(ISNUMBER(_xlpm.b), AND(_xlpm.b<>0, _xlpm.b*2<=_xlpm.r), FALSE) ), AND( OR(_xlpm.s={"NOT_FOUND","BACK_ORDER_OOS"}), _xlpm.d>30 ) ) )} -> TRUE | M13: =_xlfn.XLOOKUP(BUYLIST10[[#This Row],[NAME]],summary_prices[game],summary_prices[best_in_stock_store]) -> Gameology | N13: =HYPERLINK(_xlfn.XLOOKUP(BUYLIST10[[#This Row],[BGG ID]],STOREURL[BGG ID],STOREURL[BGO LINK])) -> https://www.boardgameoracle.com/en-NZ/boardgame/price/01S6no2BbD/orleans | O13: =COUNTIF(OWNED[bgg_id],BUYLIST10[[#This Row],[BGG ID]]) -> 0 | P13: =COUNTIF(BUYLIST10[NAME],BUYLIST10[[#This Row],[NAME]]) -> 1
... A95: 99 | B95: =IFERROR(_xlfn.XLOOKUP(BUYLIST10[[#This Row],[BGG ID]],bgg_cache[id],bgg_cache[title]),_xlfn.XLOOKUP(BUYLIST10[[#This Row],[BGG ID]],manual_bgg!B:B,manual_bgg!D:D)) -> El Grande: Big Box | C95: =_xlfn.IMAGE(_xlfn.XLOOKUP(BUYLIST10[[#This Row],[BGG ID]],bgg_cache[id],bgg_cache[thumbnail_url]),,3,80) -> #N/A | D95: 171908 | E95: =_xlfn.XLOOKUP(BUYLIST10[[#This Row],[BGG ID]],STOREURL[BGG ID],STOREURL[STATUS]) -> NOT_FOUND | F95: =_xlfn.XLOOKUP(BUYLIST10[[#This Row],[BGG ID]],STOREURL[BGG ID],STOREURL[LPG_RRP]) -> 0 | G95: =_xlfn.XLOOKUP(BUYLIST10[[#This Row],[NAME]],summary_prices[game],summary_prices[site_low_nzd]) -> 81.52 | H95: =_xlfn.XLOOKUP(BUYLIST10[[#This Row],[NAME]],summary_prices[game],summary_prices[site_mean_nzd]) -> 90.26 | I95: =_xlfn.XLOOKUP(BUYLIST10[[#This Row],[NAME]],summary_prices[game],summary_prices[best_in_stock_nzd]) -> 0 | J95: =IFERROR(_xlfn.XLOOKUP(BUYLIST10[[#This Row],[NAME]],summary_prices[game],summary_prices[discount_pct_vs_site_mean]),-99) -> 0 | K95: =_xlfn.XLOOKUP(BUYLIST10[[#This Row],[NAME]],summary_prices[game],summary_prices[delta_vs_site_disc_mean_pp]) -> 0 | L95: {=_xlfn.LET( _xlpm.b, BUYLIST10[[#This Row],[BEST]], _xlpm.s, BUYLIST10[[#This Row],[LPG_Status]], _xlpm.r, BUYLIST10[[#This Row],[LPG_RRP]], _xlpm.d, BUYLIST10[[#This Row],[Discount]], OR( AND( OR(_xlpm.s={"AVAILABLE","BACK_ORDER"}), IF(ISNUMBER(_xlpm.b), AND(_xlpm.b<>0, _xlpm.b*2<=_xlpm.r), FALSE) ), AND( OR(_xlpm.s={"NOT_FOUND","BACK_ORDER_OOS"}), _xlpm.d>30 ) ) )} -> FALSE | M95: =_xlfn.XLOOKUP(BUYLIST10[[#This Row],[NAME]],summary_prices[game],summary_prices[best_in_stock_store]) | N95: =HYPERLINK(_xlfn.XLOOKUP(BUYLIST10[[#This Row],[BGG ID]],STOREURL[BGG ID],STOREURL[BGO LINK])) -> https://www.boardgameoracle.com/en-NZ/boardgame/price/-IO6W6K0sN/el-grande | O95: =COUNTIF(OWNED[bgg_id],BUYLIST10[[#This Row],[BGG ID]]) -> 0 | P95: =COUNTIF(BUYLIST10[NAME],BUYLIST10[[#This Row],[NAME]]) -> 1

Sheet LIBRARY
A1: id | B1: title | C1: categories | D1: year | E1: players_min | F1: players_max | G1: playtime_min | H1: playtime_max | I1: thumbnail_url | J1: image | K1: created_at | L1: bgg_id | M1: thumbnail_file | N1: mana_meeple_category | O1: description | P1: designers | Q1: publishers | R1: mechanics | S1: artists | T1: average_rating | U1: complexity | V1: bgg_rank | W1: users_rated | X1: min_age | Y1: is_cooperative | Z1: nz_designer | AA1: game_type | AB1: in_owned
A2: 1 | B2: Azul | C2: Abstract Strategy, Renaissance | D2: 2017 | E2: 2 | F2: 4 | G2: 30 | H2: 45 | I2: /thumbs/1-azul.png | J2: https://cf.geekdo-images.com/aPSHJO0d0XOpQR5X-wJonw__original/img/AkbtYVc6xXJF3c9EUrakklcclKw=/0x0/filters:format(png)/pic6973671.png | K2: 2025-09-16T00:47:26.336168 | L2: 230802 | M2: 1-azul.png | N2: GATEWAY_STRATEGY | O2: Introduced by the Moors, azulejos (originally white and blue ceramic tiles) were fully embraced by the Portuguese when their king Manuel I, on a visit to the Alhambra palace in Southern Spain, was mesmerized by the stunning beauty of the Moorish decorative tiles. The king, awestruck by the interior beauty of the Alhambra, immediately ordered that his own palace in Portugal be decorated with similar wall tiles. As a tile-laying artist, you have been challenged to embellish the walls of the Royal Palace of Evora. In the game Azul, players take turns drafting colored tiles from suppliers to their player board. Later in the round, players score points based on how they've placed their tiles to decorate the palace. Extra points are scored for specific patterns and completing sets; wasted supplies harm the player's score. The player with the most points at the end of the game wins. | P2: ["Michael Kiesling"] | Q2: ["Next Move Games", "Plan B Games", "asmodee", "Belleville (\u0411\u0435\u043b\u044c\u0432\u0456\u043b\u044c)", "Broadway Toys LTD", "Divercentro", "Gal\u00e1pagos Jogos", "G\u00e9m Klub Kft.", "Ghenos Games", "Green Elephant Games", "Hobby Japan", "KADABRA", "Kaissa Chess & Games", "Korea Boardgames", "Lacerta", "MINDOK", "MIPL", "Orangutan Games", "Pegasus Spiele", "Rebel Sp. z o.o.", "SuperHeated Neurons", "Tower Tactic Games", "TWOPLUS Games", "Zvezda"] | R2: ["Chaining", "End Game Bonuses", "Grid Coverage", "Open Drafting", "Pattern Building", "Set Collection", "Square Grid", "Tile Placement", "Turn Order: Claim Action"] | S2: ["Philippe Gu\u00e9rin", "Chris Quilliams"] | T2: 7.72407 | U2: 1.7742 | V2: 91 | W2: 102534 | X2: 8 | Y2: FALSE | Z2: FALSE | AA2: Abstract • Family | AB2: =COUNTIF(OWNED[bgg_id],library_data[[#This Row],[bgg_id]]) -> 1
A3: 2 | B3: Wingspan | C3: Animals, Card Game, Educational | D3: 2019 | E3: 1 | F3: 5 | G3: 40 | H3: 70 | I3: /thumbs/2-wingspan.jpg | J3: https://cf.geekdo-images.com/yLZJCVLlIx4c7eJEWUNJ7w__original/img/cI782Zis9cT66j2MjSHKJGnFPNw=/0x0/filters:format(jpeg)/pic4458123.jpg | K3: 2025-09-16T00:59:01.484382 | L3: 266192 | M3: 2-wingspan.jpg | N3: CORE_STRATEGY | O3: Wingspan is a competitive, medium-weight, card-driven, engine-building board game from Stonemaier Games. It's designed by Elizabeth Hargrave and features 180 birds illustrated by Natalia Rojas and Ana Maria Martinez. You are bird enthusiasts—researchers, bird watchers, ornithologists, and collectors—seeking to discover and attract the best birds to your network of wildlife preserves. Each bird extends a chain of powerful combinations in one of your habitats (actions). These habitats focus on several key aspects of growth: Gain food tokens via custom dice in a birdfeeder dice tower Lay eggs using egg miniatures in a variety of colors Draw from hundreds of unique bird cards and play them The winner is the player with the most points after 4 rounds. —description from the publisher From the 7th printing on, the base game box includes Wingspan: Swift-Start Promo Pack. | P3: ["Elizabeth Hargrave"] | Q3: ["Stonemaier Games", "999 Games", "Angry Lion Games", "Arclight Games", "asmodee", "Automa Factory", "Bluebird Games", "Brain Games", "Delta Vision Publishing", "Divercentro", "Feuerland Spiele", "Ghenos Games", "Green Elephant Games", "Grok Games", "Kaissa Chess & Games", "Korea Boardgames", "Lautapelit.fi", "Lavka Games", "Ludofy Creative", "Maldito Games", "Matagot", "MINDOK", "MIPL", "NeoTroy Games", "Rebel Sp. z o.o.", "Regatul Jocurilor", "Siam Board Games", "Surfin' Meeple China", "\u0406\u0433\u0440\u043e\u043c\u0430\u0433"] | R3: ["Action Queue", "Dice Rolling", "End Game Bonuses", "Hand Management", "Once-Per-Game Abilities", "Open Drafting", "Set Collection", "Solo / Solitaire Game", "Turn Order: Progressive"] | S3: ["Ana Maria Martinez Jaramillo", "Natalia Rojas", "Elizabeth Hargrave", "Greg May", "Beth Sobel"] | T3: 8.01138 | U3: 2.4754 | V3: 38 | W3: 106577 | X3: 10 | Y3: FALSE | Z3: FALSE | AA3: Family • Strategy | AB3: =COUNTIF(OWNED[bgg_id],library_data[[#This Row],[bgg_id]]) -> 1
A4: 3 | B4: Cascadia | C4: Animals, Environmental | D4: 2021 | E4: 1 | F4: 4 | G4: 30 | H4: 45 | I4: /thumbs/3-cascadia.jpg | J4: https://cf.geekdo-images.com/MjeJZfulbsM1DSV3DrGJYA__original/img/B374C04Eip7fmQBGJzgiOTp-jyQ=/0x0/filters:format(jpeg)/pic5100691.jpg | K4: 2025-09-16T00:59:18.753257 | L4: 295947 | M4: 3-cascadia.jpg | N4: GATEWAY_STRATEGY | O4: Cascadia is a puzzly tile-laying and token-drafting game featuring the habitats and wildlife of the Pacific Northwest. In the game, you take turns building out your own terrain area and populating it with wildlife. You start with three hexagonal habitat tiles (with the five types of habitat in the game), and on a turn you choose a new habitat tile that's paired with a wildlife token, then place that tile next to your other ones and place the wildlife token on an appropriate habitat. (Each tile depicts 1-3 types of wildlife from the five types in the game, and you can place at most one tile on a habitat.) Four tiles are on display, with each tile being paired at random with a wildlife token, so you must make the best of what's available — unless you have a nature token to spend so that you can pick your choice of each item. Ideally you can place habitat tiles to create matching terrain that reduces fragmentation and creates wildlife corridors, mostly because you score for the largest area of each type of habitat at game's end, with a bonus if your group is larger than each other player's. At the same time, you want to place wildlife tokens so that you can maximize the number of points scored by them, with the wildlife goals being determined at random by one of the four scoring cards for each type of wildlife. Maybe hawks want to be separate from other hawks, while foxes want lots of different animals surrounding them and bears want to be in pairs. Can you make it happen? | P4: ["Randy Flynn"] | Q4: ["Flatout Games", "Alderac Entertainment Group", "Boardgame Mall", "CMON Global Limited", "CrowD Games", "Delirium Games", "Fantasmagoria", "Gaming Library", "G\u00e9m Klub Kft.", "Grok Games", "Hid Konem (\u0425\u0456\u0434 \u041a\u043e\u043d\u0435\u043c)", "Kaissa Chess & Games", "KOSMOS", "Little Rocket Games", "Lord of Boards", "Lucky Duck Games", "MINDOK", "MIPL", "NeoTroy Games", "Regatul Jocurilor", "Salta da Caixa", "Terra Publica", "Tower Tactic Games", "White Goblin Games", "\u682a\u5f0f\u4f1a\u793e\u30b1\u30f3\u30d3\u30eb (KenBill)"] | R4: ["End Game Bonuses", "Hexagon Grid", "Open Drafting", "Pattern Building", "Solo / Solitaire Game", "Tile Placement", "Variable Set-up"] | S4: ["Beth Sobel"] | T4: 7.90913 | U4: 1.8495 | V4: 54 | W4: 50152 | X4: 10 | Y4: FALSE | Z4: FALSE | AA4: Abstract • Family | AB4: =COUNTIF(OWNED[bgg_id],library_data[[#This Row],[bgg_id]]) -> 1
A5: 4 | B5: 7 Wonders | C5: Ancient, Card Game, City Building, Civilization, Economic | D5: 2010 | E5: 2 | F5: 7 | G5: 30 | H5: 30 | I5: /thumbs/4-7-wonders.jpg | J5: https://cf.geekdo-images.com/35h9Za_JvMMMtx_92kT0Jg__original/img/jt70jJDZ1y1FWJs4ZQf5FI8APVY=/0x0/filters:format(jpeg)/pic7149798.jpg | K5: 2025-09-16T22:42:10.050302 | L5: 68448 | M5: 4-7-wonders.jpg | N5: GATEWAY_STRATEGY | O5: You are the leader of one of the 7 great cities of the Ancient World. Gather resources, develop commercial routes, and affirm your military supremacy. Build your city and erect an architectural wonder which will transcend future times. 7 Wonders lasts three ages. In each age, players receive seven cards from a particular deck, choose one of those cards, then pass the remainder to an adjacent player. Players reveal their cards simultaneously, paying resources if needed or collecting resources or interacting with other players in various ways. (Players have individual boards with special powers on which to organize their cards, and the boards are double-sided). Each player then chooses another card from the deck they were passed, and the process repeats until players have six cards in play from that age. After three ages, the game ends. In essence, 7 Wonders is a card development game. Some cards have immediate effects, while others provide bonuses or upgrades later in the game. Some cards provide discounts on future purchases. Some provide military strength to overpower your neighbors and others give nothing but victory points. Each card is played immediately after being drafted, so you'll know which cards your neighbor is receiving and how her choices might affect what you've already built up. Cards are passed left-right-left over the three ages, so you need to keep an eye on the neighbors in both directions. Though the box of earlier editions is listed as being for 3–7 players, there is an official 2-player variant included in the instructions. | P5: ["Antoine Bauza"] | Q5: ["Repos Production", "ADC Blackfire Entertainment", "Asterion Press", "Gal\u00e1pagos Jogos", "G\u00e9m Klub Kft.", "Hobby Japan", "Kaissa Chess & Games", "Korea Boardgames", "Lautapelit.fi", "Lifestyle Boardgames Ltd", "NeoTroy Games", "Rebel Sp. z o.o.", "Siam Board Games"] | R5: ["Closed Drafting", "End Game Bonuses", "Hand Management", "Melding and Splaying", "Multi-Use Cards", "Neighbor Scope", "Once-Per-Game Abilities", "Score-and-Reset Game", "Set Collection", "Simultaneous Action Selection", "Tags", "Tech Trees / Tech Tracks", "Variable Player Powers", "Variable Set-up"] | S5: ["Dimitri Chappuis", "Miguel Coimbra", "Etienne Hebinger", "Cyril Nouvel"] | T5: 7.66798 | U5: 2.3149 | V5: 111 | W5: 110129 | X5: 10 | Y5: FALSE | Z5: FALSE | AA5: Family • Strategy | AB5: =COUNTIF(OWNED[bgg_id],library_data[[#This Row],[bgg_id]]) -> 1
